Workbook
Name helpfile: #REF!

Sheet RR BU Koncern legal IC UVXair
D4: Sacpro Group koncern | R4: ELIM | AF4: Sacpro AB | AT4: Sacpro FI | BH4: Uvrelining | BV4: Svedlunds flaggstänger | CJ4: Sacpro Group
D6: BU 2026 | E6: 2601 | F6: 2602 | G6: 2603 | H6: 2604 | I6: 2605 | J6: 2606 | K6: 2607 | L6: 2608 | M6: 2609 | N6: 2610 | O6: 2611 | P6: 2612 | R6: BU 2026 | S6: 2601 | T6: 2602 | U6: 2603 | V6: 2604 | W6: 2605 | X6: 2606 | Y6: 2607 | Z6: 2608 | AA6: 2609 | AB6: 2610 | AC6: 2611 | AD6: 2612 | AF6: BU 2026 | AG6: 2601 | AH6: 2602 | AI6: 2603 | AJ6: 2604 | AK6: 2605 | AL6: 2606 | AM6: 2607 | AN6: 2608 | AO6: 2609 | AP6: 2610 | AQ6: 2611 | AR6: 2612 | AT6: BU 2026 | AU6: 2601 | AV6: 2602 | AW6: 2603 | AX6: 2604 | AY6: 2605 | AZ6: 2606 | BA6: 2607 | BB6: 2608 | BC6: 2609 | BD6: 2610 | BE6: 2611 | BF6: 2612 | BH6: BU 2026 | BI6: 2601 | BJ6: 2602 | BK6: 2603 | BL6: 2604 | BM6: 2605 | BN6: 2606 | BO6: 2607 | BP6: 2608 | BQ6: 2609 | BR6: 2610 | BS6: 2611 | BT6: 2612 | BV6: BU 2026 | BW6: 2601 | BX6: 2602 | BY6: 2603 | BZ6: 2604 | CA6: 2605 | CB6: 2606 | CC6: 2607 | CD6: 2608 | CE6: 2609 | CF6: 2610 | CG6: 2611 | CH6: 2612 | CJ6: BU 2026 | CK6: 2601 | CL6: 2602 | CM6: 2603 | CN6: 2604 | CO6: 2605 | CP6: 2606 | CQ6: 2607 | CR6: 2608 | CS6: 2609 | CT6: 2610 | CU6: 2611 | CV6: 2612
C8: Nettoomsättning | D8: 243055.01 | E8: 16234.402 | F8: 19632.114 | G8: 18493.576 | H8: 22760.089 | I8: 22005.466 | J8: 24559.258 | K8: 9196.2409 | L8: 23041.946 | M8: 22344.531 | N8: 25218.408 | O8: 25321.703 | P8: 14247.271 | R8: -10620 | S8: -590 | T8: -1180 | U8: -590 | V8: -1180 | W8: -590 | X8: -1180 | Y8: -590 | Z8: -590 | AA8: -1180 | AB8: -1180 | AC8: -1180 | AD8: -590 | AF8: 161556.08 | AG8: 11167.015 | AH8: 13259.126 | AI8: 11802.493 | AJ8: 15432.817 | AK8: 14678.194 | AL8: 16595.797 | AM8: 6388.7387 | AN8: 14727.167 | AO8: 14699.165 | AP8: 16936.852 | AQ8: 17040.147 | AR8: 8828.5667 | AT8: 10068.271 | AU8: 654.4376 | AV8: 755.12031 | AW8: 805.46166 | AX8: 906.14437 | AY8: 906.14437 | AZ8: 1006.8271 | BA8: 402.73083 | BB8: 956.48572 | BC8: 956.48572 | BD8: 1057.1684 | BE8: 1057.1684 | BF8: 604.09625 | BH8: 79850.658 | BI8: 4819.6163 | BJ8: 6614.5346 | BK8: 6292.2879 | BL8: 7417.7945 | BM8: 6827.7945 | BN8: 7953.3011 | BO8: 2811.4381 | BP8: 7764.9596 | BQ8: 7685.5478 | BR8: 8221.0544 | BS8: 8221.0544 | BT8: 5221.2748 | BV8: 2200 | BW8: 183.33333 | BX8: 183.33333 | BY8: 183.33333 | BZ8: 183.33333 | CA8: 183.33333 | CB8: 183.33333 | CC8: 183.33333 | CD8: 183.33333 | CE8: 183.33333 | CF8: 183.33333 | CG8: 183.33333 | CH8: 183.33333 | CJ8: 0
C9: Nettoomsättning | AG9: 10577.015 | AH9: 12669.126 | AI9: 11212.493 | AJ9: 14842.817 | AK9: 14088.194 | AL9: 16005.797 | AM9: 5798.7387 | AN9: 14137.167 | AO9: 14109.165 | AP9: 16346.852 | AQ9: 16450.147 | AR9: 8238.5667 | AU9: 654.4376 | AV9: 755.12031 | AW9: 805.46166 | AX9: 906.14437 | AY9: 906.14437 | AZ9: 1006.8271 | BA9: 402.73083 | BB9: 956.48572 | BC9: 956.48572 | BD9: 1057.1684 | BE9: 1057.1684 | BF9: 604.09625 | BI9: 4229.6163 | BJ9: 5434.5346 | BK9: 5702.2879 | BL9: 6237.7945 | BM9: 6237.7945 | BN9: 6773.3011 | BO9: 2221.4381 | BP9: 7174.9596 | BQ9: 6505.5478 | BR9: 7041.0544 | BS9: 7041.0544 | BT9: 4631.2748
C10: UVXAir elim | S10: -590 | T10: -1180 | U10: -590 | V10: -1180 | W10: -590 | X10: -1180 | Y10: -590 | Z10: -590 | AA10: -1180 | AB10: -1180 | AC10: -1180 | AD10: -590 | AG10: 590 | AH10: 590 | AI10: 590 | AJ10: 590 | AK10: 590 | AL10: 590 | AM10: 590 | AN10: 590 | AO10: 590 | AP10: 590 | AQ10: 590 | AR10: 590 | BI10: 590 | BJ10: 1180 | BK10: 590 | BL10: 1180 | BM10: 590 | BN10: 1180 | BO10: 590 | BP10: 590 | BQ10: 1180 | BR10: 1180 | BS10: 1180 | BT10: 590
C12: Övriga rörelseintäkter | D12: 1860 | E12: 155 | F12: 155 | G12: 155 | H12: 155 | I12: 155 | J12: 155 | K12: 155 | L12: 155 | M12: 155 | N12: 155 | O12: 155 | P12: 155 | R12: 0 | AF12: 1200 | AG12: 100 | AH12: 100 | AI12: 100 | AJ12: 100 | AK12: 100 | AL12: 100 | AM12: 100 | AN12: 100 | AO12: 100 | AP12: 100 | AQ12: 100 | AR12: 100 | AT12: 0 | BH12: 660 | BI12: 55 | BJ12: 55 | BK12: 55 | BL12: 55 | BM12: 55 | BN12: 55 | BO12: 55 | BP12: 55 | BQ12: 55 | BR12: 55 | BS12: 55 | BT12: 55 | BV12: 0 | CJ12: 0
C14: Direkta materialkostnader | D14: -147316.14 | E14: -10737.715 | F14: -12553.594 | G14: -11940.033 | H14: -13935.413 | I14: -13523.413 | J14: -14685.792 | K14: -5040.5167 | L14: -13922.852 | M14: -13014.575 | N14: -14912.731 | O14: -14993.231 | P14: -8056.275 | R14: 10620 | S14: 590 | T14: 1180 | U14: 590 | V14: 1180 | W14: 590 | X14: 1180 | Y14: 590 | Z14: 590 | AA14: 1180 | AB14: 1180 | AC14: 1180 | AD14: 590 | AF14: -96178.02 | AG14: -7455.6608 | AH14: -8707.6548 | AI14: -7647.6518 | AJ14: -9440.1458 | AK14: -8798.1458 | AL14: -9757.6397 | AM14: -3201.6759 | AN14: -8620.1428 | AO14: -8302.8657 | AP14: -9768.1367 | AQ14: -9848.6367 | AR14: -4629.6638 | AT14: -6881.8043 | AU14: -447.31728 | AV14: -516.13532 | AW14: -550.54434 | AX14: -619.36239 | AY14: -619.36239 | AZ14: -688.18043 | BA14: -275.27217 | BB14: -653.77141 | BC14: -653.77141 | BD14: -722.58945 | BE14: -722.58945 | BF14: -412.90826 | BH14: -50840.716 | BI14: -3088.4365 | BJ14: -4173.5037 | BK14: -3995.5373 | BL14: -4719.6044 | BM14: -4359.6044 | BN14: -5083.6716 | BO14: -1817.2686 | BP14: -4902.638 | BQ14: -4901.638 | BR14: -5265.7052 | BS14: -5265.7052 | BT14: -3267.4029 | BV14: -4035.6 | BW14: -336.3 | BX14: -336.3 | BY14: -336.3 | BZ14: -336.3 | CA14: -336.3 | CB14: -336.3 | CC14: -336.3 | CD14: -336.3 | CE14: -336.3 | CF14: -336.3 | CG14: -336.3 | CH14: -336.3 | CJ14: 0
C15: Direkta materialkostnader | AG15: -7121.9608 | AH15: -8143.9548 | AI15: -7313.9518 | AJ15: -8876.4458 | AK15: -8464.4458 | AL15: -9193.9397 | AM15: -2867.9759 | AN15: -8286.4428 | AO15: -7739.1657 | AP15: -9204.4367 | AQ15: -9284.9367 | AR15: -4295.9638 | AT15: -6881.8043 | AU15: -447.31728 | AV15: -516.13532 | AW15: -550.54434 | AX15: -619.36239 | AY15: -619.36239 | AZ15: -688.18043 | BA15: -275.27217 | BB15: -653.77141 | BC15: -653.77141 | BD15: -722.58945 | BE15: -722.58945 | BF15: -412.90826 | BI15: -2728.4365 | BJ15: -3453.5037 | BK15: -3635.5373 | BL15: -3999.6044 | BM15: -3999.6044 | BN15: -4363.6716 | BO15: -1457.2686 | BP15: -4542.638 | BQ15: -4181.638 | BR15: -4545.7052 | BS15: -4545.7052 | BT15: -2907.4029 | BW15: -80 | BX15: -80 | BY15: -80 | BZ15: -80 | CA15: -80 | CB15: -80 | CC15: -80 | CD15: -80 | CE15: -80 | CF15: -80 | CG15: -80 | CH15: -80
C16: MO ink lager | D16: 0 | E16: 0 | F16: 0 | G16: 0 | H16: 0 | I16: 0 | J16: 0 | K16: 0 | L16: 0 | M16: 0 | N16: 0 | O16: 0 | P16: 0 | AG16: 256.3 | AH16: 256.3 | AI16: 256.3 | AJ16: 256.3 | AK16: 256.3 | AL16: 256.3 | AM16: 256.3 | AN16: 256.3 | AO16: 256.3 | AP16: 256.3 | AQ16: 256.3 | AR16: 256.3 | AT16: 0 | BW16: -256.3 | BX16: -256.3 | BY16: -256.3 | BZ16: -256.3 | CA16: -256.3 | CB16: -256.3 | CC16: -256.3 | CD16: -256.3 | CE16: -256.3 | CF16: -256.3 | CG16: -256.3 | CH16: -256.3 | CJ16: 0
C17: Direkt lön | D17: 0 | E17: 0 | F17: 0 | G17: 0 | H17: 0 | I17: 0 | J17: 0 | K17: 0 | L17: 0 | M17: 0 | N17: 0 | O17: 0 | P17: 0 | AT17: 0 | CJ17: 0
C18: UVXair elim | S18: 590 | T18: 1180 | U18: 590 | V18: 1180 | W18: 590 | X18: 1180 | Y18: 590 | Z18: 590 | AA18: 1180 | AB18: 1180 | AC18: 1180 | AD18: 590 | AG18: -590 | AH18: -820 | AI18: -590 | AJ18: -820 | AK18: -590 | AL18: -820 | AM18: -590 | AN18: -590 | AO18: -820 | AP18: -820 | AQ18: -820 | AR18: -590 | AT18: 0 | BI18: -360 | BJ18: -720 | BK18: -360 | BL18: -720 | BM18: -360 | BN18: -720 | BO18: -360 | BP18: -360 | BQ18: -720 | BR18: -720 | BS18: -720 | BT18: -360
C20: Bruttovinst | D20: 95738.866 | E20: 5496.6876 | F20: 7078.5203 | G20: 6553.5421 | H20: 8824.6766 | I20: 8482.0538 | J20: 9873.4665 | K20: 4155.7242 | L20: 9119.0939 | M20: 9329.9564 | N20: 10305.677 | O20: 10328.472 | P20: 6190.996 | R20: 0 | S20: 0 | T20: 0 | U20: 0 | V20: 0 | W20: 0 | X20: 0 | Y20: 0 | Z20: 0 | AA20: 0 | AB20: 0 | AC20: 0 | AD20: 0 | AF20: 65378.058 | AG20: 3711.3542 | AH20: 4551.471 | AI20: 4154.8408 | AJ20: 5992.6712 | AK20: 5880.0483 | AL20: 6838.157 | AM20: 3187.0628 | AN20: 6107.0247 | AO20: 6396.2989 | AP20: 7168.7154 | AQ20: 7191.5105 | AR20: 4198.9029 | AT20: 3186.4665 | AU20: 207.12032 | AV20: 238.98498 | AW20: 254.91732 | AX20: 286.78198 | AY20: 286.78198 | AZ20: 318.64665 | BA20: 127.45866 | BB20: 302.71431 | BC20: 302.71431 | BD20: 334.57898 | BE20: 334.57898 | BF20: 191.18799 | BH20: 29009.942 | BI20: 1731.1798 | BJ20: 2441.031 | BK20: 2296.7507 | BL20: 2698.1901 | BM20: 2468.1901 | BN20: 2869.6295 | BO20: 994.16946 | BP20: 2862.3216 | BQ20: 2783.9098 | BR20: 2955.3492 | BS20: 2955.3492 | BT20: 1953.8718 | BV20: -1835.6 | BW20: -152.96667 | BX20: -152.96667 | BY20: -152.96667 | BZ20: -152.96667 | CA20: -152.96667 | CB20: -152.96667 | CC20: -152.96667 | CD20: -152.96667 | CE20: -152.96667 | CF20: -152.96667 | CG20: -152.96667 | CH20: -152.96667 | CJ20: 0 | CK20: 0 | CL20: 0 | CM20: 0 | CN20: 0 | CO20: 0 | CP20: 0 | CQ20: 0 | CR20: 0 | CS20: 0 | CT20: 0 | CU20: 0 | CV20: 0
C21: % | D21: 0.39389794 | E21: 0.33858269 | F21: 0.36055823 | G21: 0.35436858 | H21: 0.38772592 | I21: 0.38545213 | J21: 0.40202625 | K21: 0.4518938 | L21: 0.39576058 | M21: 0.41754988 | N21: 0.40865692 | O21: 0.4078901 | P21: 0.43453908 | R21: 0 | S21: 0 | T21: 0 | U21: 0 | V21: 0 | W21: 0 | X21: 0 | Y21: 0 | Z21: 0 | AA21: 0 | AB21: 0 | AC21: 0 | AD21: 0 | AF21: 0.40467718 | AG21: 0.33234971 | AH21: 0.34327082 | AI21: 0.35203079 | AJ21: 0.38830702 | AK21: 0.40059753 | AL21: 0.4120415 | AM21: 0.49885634 | AN21: 0.41467748 | AO21: 0.43514711 | AP21: 0.42326138 | AQ21: 0.42203335 | AR21: 0.47560414 | AT21: 0.31648597 | AU21: 0.31648597 | AV21: 0.31648597 | AW21: 0.31648597 | AX21: 0.31648597 | AY21: 0.31648597 | AZ21: 0.31648597 | BA21: 0.31648597 | BB21: 0.31648597 | BC21: 0.31648597 | BD21: 0.31648597 | BE21: 0.31648597 | BF21: 0.31648597 | BH21: 0.36330248 | BI21: 0.35919452 | BJ21: 0.36904047 | BK21: 0.36501042 | BL21: 0.3637456 | BM21: 0.36149156 | BN21: 0.36080987 | BO21: 0.35361599 | BP21: 0.36862028 | BQ21: 0.36222659 | BR21: 0.35948543 | BS21: 0.35948543 | BT21: 0.37421356 | BV21: -0.83436364 | BW21: -0.83436364 | BX21: -0.83436364 | BY21: -0.83436364 | BZ21: -0.83436364 | CA21: -0.83436364 | CB21: -0.83436364 | CC21: -0.83436364 | CD21: -0.83436364 | CE21: -0.83436364 | CF21: -0.83436364 | CG21: -0.83436364 | CH21: -0.83436364 | CJ21: #DIV/0! | CK21: #DIV/0! | CL21: #DIV/0! | CM21: #DIV/0! | CN21: #DIV/0! | CO21: #DIV/0! | CP21: #DIV/0! | CQ21: #DIV/0! | CR21: #DIV/0! | CS21: #DIV/0! | CT21: #DIV/0! | CU21: #DIV/0! | CV21: #DIV/0!
C23: Övriga externa kostnader | D23: -22768.053 | E23: -1713.5982 | F23: -1930.1973 | G23: -1737.6656 | H23: -1693.0574 | I23: -2226.2104 | J23: -2057.5283 | K23: -1829.3486 | L23: -1912.7559 | M23: -1847.6128 | N23: -2073.4895 | O23: -1877.0631 | P23: -1869.5258 | R23: 0 | AF23: -13741.543 | AG23: -1031.2153 | AH23: -1231.5978 | AI23: -1032.1033 | AJ23: -1038.0436 | AK23: -1531.9528 | AL23: -1031.9763 | AM23: -1038.9913 | AN23: -1119.49 | AO23: -1119.55 | AP23: -1326.554 | AQ23: -1120.034 | AR23: -1120.034 | AT23: -1252.02 | AU23: -99.385 | AV23: -99.385 | AW23: -99.385 | AX23: -99.385 | AY23: -99.385 | AZ23: -158.785 | BA23: -99.385 | BB23: -99.385 | BC23: -99.385 | BD23: -99.385 | BE23: -99.385 | BF23: -99.385 | BH23: -6041.5833 | BI23: -464.66667 | BJ23: -456.33333 | BK23: -464.66667 | BL23: -456.33333 | BM23: -464.66667 | BN23: -685.91667 | BO23: -512.33333 | BP23: -504 | BQ23: -512.33333 | BR23: -504 | BS23: -512.33333 | BT23: -504 | BV23: -1114.9071 | BW23: -76.8312 | BX23: -101.38111 | BY23: -70.01063 | BZ23: -57.7955 | CA23: -88.70589 | CB23: -109.35032 | CC23: -137.13896 | CD23: -148.38087 | CE23: -44.844477 | CF23: -102.0505 | CG23: -103.81081 | CH23: -74.60685 | CJ23: -618 | CK23: -41.5 | CL23: -41.5 | CM23: -71.5 | CN23: -41.5 | CO23: -41.5 | CP23: -71.5 | CQ23: -41.5 | CR23: -41.5 | CS23: -71.5 | CT23: -41.5 | CU23: -41.5 | CV23: -71.5
C24: Personalkostnader | D24: -31163.084 | E24: -2391.6147 | F24: -2518.7223 | G24: -2489.9568 | H24: -2496.2498 | I24: -2814.8583 | J24: -2964.3527 | K24: -694.68225 | L24: -3008.5089 | M24: -2937.0353 | N24: -2824.2099 | O24: -3033.0646 | P24: -2989.8288 | R24: 0 | AF24: -18253.513 | AG24: -1345.1975 | AH24: -1345.1975 | AI24: -1345.1975 | AJ24: -1384.5335 | AK24: -1594.7249 | AL24: -1815.7012 | AM24: -344.45479 | AN24: -1815.7012 | AO24: -1815.7012 | AP24: -1815.7012 | AQ24: -1815.7012 | AR24: -1815.7012 | AT24: -1495.3 | AU24: -132.73333 | AV24: -132.73333 | AW24: -132.73333 | AX24: -132.73333 | AY24: -132.73333 | AZ24: -132.73333 | BA24: -46.233333 | BB24: -121.73333 | BC24: -132.73333 | BD24: -132.73333 | BE24: -132.73333 | BF24: -132.73333 | BH24: -6949.2867 | BI24: -616.49916 | BJ24: -616.49916 | BK24: -616.49916 | BL24: -628.20449 | BM24: -628.20449 | BN24: -628.20449 | BO24: -74.153329 | BP24: -628.20449 | BQ24: -628.20449 | BR24: -628.20449 | BS24: -628.20449 | BT24: -628.20449 | BV24: -2562.2057 | BW24: -130.4935 | BX24: -257.60111 | BY24: -228.83562 | BZ24: -179.93022 | CA24: -288.34722 | CB24: -216.86536 | CC24: -193.9219 | CD24: -272.02158 | CE24: -189.54794 | CF24: -76.722539 | CG24: -285.57723 | CH24: -242.34143 | CJ24: -1902.7792 | CK24: -166.69122 | CL24: -166.69122 | CM24: -166.69122 | CN24: -170.84834 | CO24: -170.84834 | CP24: -170.84834 | CQ24: -35.918897 | CR24: -170.84834 | CS24: -170.84834 | CT24: -170.84834 | CU24: -170.84834 | CV24: -170.84834
C26: EBITDA | D26: 43667.729 | E26: 1546.4747 | F26: 2784.6007 | G26: 2480.9197 | H26: 4790.3693 | I26: 3595.9851 | J26: 5006.5854 | K26: 1786.6934 | L26: 4352.8291 | M26: 4700.3083 | N26: 5562.9775 | O26: 5573.3443 | P26: 1486.6414 | R26: 0 | S26: 0 | T26: 0 | U26: 0 | V26: 0 | W26: 0 | X26: 0 | Y26: 0 | Z26: 0 | AA26: 0 | AB26: 0 | AC26: 0 | AD26: 0 | AF26: 34583.002 | AG26: 1434.9414 | AH26: 2074.6757 | AI26: 1877.54 | AJ26: 3670.0941 | AK26: 2853.3706 | AL26: 4090.4794 | AM26: 1903.6167 | AN26: 3271.8335 | AO26: 3561.0477 | AP26: 4126.4602 | AQ26: 4355.7753 | AR26: 1363.1677 | AT26: 439.14646 | AU26: -24.998014 | AV26: 6.8666509 | AW26: 22.798983 | AX26: 54.663648 | AY26: 54.663648 | AZ26: 27.128312 | BA26: -18.159675 | BB26: 81.59598 | BC26: 70.59598 | BD26: 102.46064 | BE26: 102.46064 | BF26: -40.930346 | BH26: 16679.072 | BI26: 705.01395 | BJ26: 1423.1985 | BK26: 1270.5848 | BL26: 1668.6523 | BM26: 1430.3189 | BN26: 1610.5084 | BO26: 462.68279 | BP26: 1785.1171 | BQ26: 1698.372 | BR26: 1878.1447 | BS26: 1869.8114 | BT26: 876.66734 | BV26: -5512.7128 | BW26: -360.29136 | BX26: -511.94889 | BY26: -451.81292 | BZ26: -390.69239 | CA26: -530.01978 | CB26: -479.18235 | CC26: -484.02752 | CD26: -573.36912 | CE26: -387.35909 | CF26: -331.73971 | CG26: -542.3547 | CH26: -469.91495 | CJ26: -2520.7792 | CK26: -208.19122 | CL26: -208.19122 | CM26: -238.19122 | CN26: -212.34834 | CO26: -212.34834 | CP26: -242.34834 | CQ26: -77.418897 | CR26: -212.34834 | CS26: -242.34834 | CT26: -212.34834 | CU26: -212.34834 | CV26: -242.34834
C27: % | D27: 0.17829748 | E27: 0.094358215 | F27: 0.14072798 | G27: 0.13303534 | H27: 0.20904869 | I27: 0.16227028 | J27: 0.20257883 | K27: 0.19106484 | L27: 0.18764664 | M27: 0.20890694 | N27: 0.21924439 | O27: 0.21876238 | P27: 0.10322271 | R27: 0 | S27: 0 | T27: 0 | U27: 0 | V27: 0 | W27: 0 | X27: 0 | Y27: 0 | Z27: 0 | AA27: 0 | AB27: 0 | AC27: 0 | AD27: 0 | AF27: 0.21248363 | AG27: 0.12735772 | AH27: 0.15530026 | AI27: 0.15774343 | AJ27: 0.23628001 | AK27: 0.19307979 | AL27: 0.24500055 | AM27: 0.29337237 | AN27: 0.22066477 | AO27: 0.24062492 | AP27: 0.2422079 | AQ27: 0.25412706 | AR27: 0.15267486 | AT27: 0.04361687 | AU27: -0.038197704 | AV27: 0.0090934528 | AW27: 0.028305485 | AX27: 0.060325539 | AY27: 0.060325539 | AZ27: 0.026944361 | BA27: -0.045091346 | BB27: 0.0853081 | BC27: 0.073807667 | BD27: 0.096919887 | BE27: 0.096919887 | BF27: -0.067754677 | BH27: 0.20716602 | BI27: 0.14462963 | BJ27: 0.21338797 | BK27: 0.2001776 | BL27: 0.22329696 | BM27: 0.20781079 | BN27: 0.20110487 | BO27: 0.16141385 | BP27: 0.22827702 | BQ27: 0.21941238 | BR27: 0.22693722 | BS27: 0.2259303 | BT27: 0.16615271 | BV27: -2.5057785 | BW27: -1.9652256 | BX27: -2.7924485 | BY27: -2.4644341 | BZ27: -2.1310494 | CA27: -2.891017 | CB27: -2.6137219 | CC27: -2.6401501 | CD27: -3.1274679 | CE27: -2.1128677 | CF27: -1.8094893 | CG27: -2.9582984 | CH27: -2.5631724 | CJ27: #DIV/0! | CK27: #DIV/0! | CL27: #DIV/0! | CM27: #DIV/0! | CN27: #DIV/0! | CO27: #DIV/0! | CP27: #DIV/0! | CQ27: #DIV/0! | CR27: #DIV/0! | CS27: #DIV/0! | CT27: #DIV/0! | CU27: #DIV/0! | CV27: #DIV/0!
C29: Avskrivningar | D29: -4038 | E29: -336.5 | F29: -336.5 | G29: -336.5 | H29: -336.5 | I29: -336.5 | J29: -336.5 | K29: -336.5 | L29: -336.5 | M29: -336.5 | N29: -336.5 | O29: -336.5 | P29: -336.5 | R29: 0 | AF29: -4038 | AG29: -336.5 | AH29: -336.5 | AI29: -336.5 | AJ29: -336.5 | AK29: -336.5 | AL29: -336.5 | AM29: -336.5 | AN29: -336.5 | AO29: -336.5 | AP29: -336.5 | AQ29: -336.5 | AR29: -336.5 | AT29: 0 | BH29: 0 | BV29: 0 | CJ29: 0
C31: EBITA | D31: 39629.729 | E31: 1209.9747 | F31: 2448.1007 | G31: 2144.4197 | H31: 4453.8693 | I31: 3259.4851 | J31: 4670.0854 | K31: 1450.1934 | L31: 4016.3291 | M31: 4363.8083 | N31: 5226.4775 | O31: 5236.8443 | P31: 1150.1414 | R31: 0 | S31: 0 | T31: 0 | U31: 0 | V31: 0 | W31: 0 | X31: 0 | Y31: 0 | Z31: 0 | AA31: 0 | AB31: 0 | AC31: 0 | AD31: 0 | AF31: 30545.002 | AG31: 1098.4414 | AH31: 1738.1757 | AI31: 1541.04 | AJ31: 3333.5941 | AK31: 2516.8706 | AL31: 3753.9794 | AM31: 1567.1167 | AN31: 2935.3335 | AO31: 3224.5477 | AP31: 3789.9602 | AQ31: 4019.2753 | AR31: 1026.6677 | AT31: 439.14646 | AU31: -24.998014 | AV31: 6.8666509 | AW31: 22.798983 | AX31: 54.663648 | AY31: 54.663648 | AZ31: 27.128312 | BA31: -18.159675 | BB31: 81.59598 | BC31: 70.59598 | BD31: 102.46064 | BE31: 102.46064 | BF31: -40.930346 | BH31: 16679.072 | BI31: 705.01395 | BJ31: 1423.1985 | BK31: 1270.5848 | BL31: 1668.6523 | BM31: 1430.3189 | BN31: 1610.5084 | BO31: 462.68279 | BP31: 1785.1171 | BQ31: 1698.372 | BR31: 1878.1447 | BS31: 1869.8114 | BT31: 876.66734 | BV31: -5512.7128 | BW31: -360.29136 | BX31: -511.94889 | BY31: -451.81292 | BZ31: -390.69239 | CA31: -530.01978 | CB31: -479.18235 | CC31: -484.02752 | CD31: -573.36912 | CE31: -387.35909 | CF31: -331.73971 | CG31: -542.3547 | CH31: -469.91495 | CJ31: -2520.7792 | CK31: -208.19122 | CL31: -208.19122 | CM31: -238.19122 | CN31: -212.34834 | CO31: -212.34834 | CP31: -242.34834 | CQ31: -77.418897 | CR31: -212.34834 | CS31: -242.34834 | CT31: -212.34834 | CU31: -212.34834 | CV31: -242.34834
C32: % | D32: 0.16181013 | E32: 0.073826655 | F32: 0.12372197 | G32: 0.11499107 | H32: 0.19436404 | I32: 0.14708558 | J32: 0.18896321 | K32: 0.15508031 | L32: 0.17314042 | M32: 0.19395107 | N32: 0.20598248 | O32: 0.20555424 | P32: 0.079858336 | R32: 0 | S32: 0 | T32: 0 | U32: 0 | V32: 0 | W32: 0 | X32: 0 | Y32: 0 | Z32: 0 | AA32: 0 | AB32: 0 | AC32: 0 | AD32: 0 | AF32: 0.1876735 | AG32: 0.097491783 | AH32: 0.13011148 | AI32: 0.12947204 | AJ32: 0.2146162 | AK32: 0.17030975 | AL32: 0.22484578 | AM32: 0.2415133 | AN32: 0.19796994 | AO32: 0.21788715 | AP32: 0.2224566 | AQ32: 0.23449479 | AR32: 0.11498684 | AT32: 0.04361687 | AU32: -0.038197704 | AV32: 0.0090934528 | AW32: 0.028305485 | AX32: 0.060325539 | AY32: 0.060325539 | AZ32: 0.026944361 | BA32: -0.045091346 | BB32: 0.0853081 | BC32: 0.073807667 | BD32: 0.096919887 | BE32: 0.096919887 | BF32: -0.067754677 | BH32: 0.20716602 | BI32: 0.14462963 | BJ32: 0.21338797 | BK32: 0.2001776 | BL32: 0.22329696 | BM32: 0.20781079 | BN32: 0.20110487 | BO32: 0.16141385 | BP32: 0.22827702 | BQ32: 0.21941238 | BR32: 0.22693722 | BS32: 0.2259303 | BT32: 0.16615271 | BV32: -2.5057785 | BW32: -1.9652256 | BX32: -2.7924485 | BY32: -2.4644341 | BZ32: -2.1310494 | CA32: -2.891017 | CB32: -2.6137219 | CC32: -2.6401501 | CD32: -3.1274679 | CE32: -2.1128677 | CF32: -1.8094893 | CG32: -2.9582984 | CH32: -2.5631724 | CJ32: #DIV/0! | CK32: #DIV/0! | CL32: #DIV/0! | CM32: #DIV/0! | CN32: #DIV/0! | CO32: #DIV/0! | CP32: #DIV/0! | CQ32: #DIV/0! | CR32: #DIV/0! | CS32: #DIV/0! | CT32: #DIV/0! | CU32: #DIV/0! | CV32: #DIV/0!
C34: Goodwill - avskrivning | D34: -17052 | E34: -1421 | F34: -1421 | G34: -1421 | H34: -1421 | I34: -1421 | J34: -1421 | K34: -1421 | L34: -1421 | M34: -1421 | N34: -1421 | O34: -1421 | P34: -1421 | R34: 0 | AF34: 0 | AT34: 0 | BH34: 0 | BV34: 0 | CJ34: 0
C36: EBIT | D36: 22577.729 | E36: -211.02526 | F36: 1027.1007 | G36: 723.41968 | H36: 3032.8693 | I36: 1838.4851 | J36: 3249.0854 | K36: 29.193365 | L36: 2595.3291 | M36: 2942.8083 | N36: 3805.4775 | O36: 3815.8443 | P36: -270.8586 | R36: 0 | S36: 0 | T36: 0 | U36: 0 | V36: 0 | W36: 0 | X36: 0 | Y36: 0 | Z36: 0 | AA36: 0 | AB36: 0 | AC36: 0 | AD36: 0 | AF36: 30545.002 | AG36: 1098.4414 | AH36: 1738.1757 | AI36: 1541.04 | AJ36: 3333.5941 | AK36: 2516.8706 | AL36: 3753.9794 | AM36: 1567.1167 | AN36: 2935.3335 | AO36: 3224.5477 | AP36: 3789.9602 | AQ36: 4019.2753 | AR36: 1026.6677 | AT36: 439.14646 | BH36: 16679.072 | BV36: -5512.7128 | CJ36: -2520.7792
C38: Finansiellt netto | D38: -3360 | E38: -280 | F38: -280 | G38: -280 | H38: -280 | I38: -280 | J38: -280 | K38: -280 | L38: -280 | M38: -280 | N38: -280 | O38: -280 | P38: -280 | R38: 0 | AF38: 0 | AT38: 0 | BH38: 0 | BV38: 0 | CJ38: 0
C40: EBT | D40: 19217.729 | E40: -491.02526 | F40: 747.10069 | G40: 443.41968 | H40: 2752.8693 | I40: 1558.4851 | J40: 2969.0854 | K40: -250.80663 | L40: 2315.3291 | M40: 2662.8083 | N40: 3525.4775 | O40: 3535.8443 | P40: -550.8586 | R40: 0 | AF40: 30545.002 | AT40: 439.14646 | BH40: 16679.072 | BV40: -5512.7128 | CJ40: -2520.7792
C42: Skatt | D42: -7471.5642 | E42: -191.5748 | F42: -446.62874 | G42: -384.07045 | H42: -859.81708 | I42: -613.77393 | J42: -904.3576 | K42: -241.05983 | L42: -769.68379 | M42: -841.2645 | N42: -1018.9744 | O42: -1021.1099 | P42: -179.24913 | R42: 0 | AF42: 0 | AT42: 0 | BH42: 0 | BV42: 0 | CJ42: 0
C44: NP | D44: 11746.165 | E44: -682.60005 | F44: 300.47195 | G44: 59.349225 | H44: 1893.0523 | I44: 944.71117 | J44: 2064.7278 | K44: -491.86647 | L44: 1545.6453 | M44: 1821.5438 | N44: 2506.5032 | O44: 2514.7344 | P44: -730.10773 | R44: 0 | AF44: 30545.002 | AT44: 439.14646 | BH44: 16679.072 | BV44: -5512.7128 | CJ44: -2520.7792
D47: 0.39389794 | E47: 0.33858269 | F47: 0.36055823 | G47: 0.35436858 | H47: 0.38772592 | I47: 0.38545213 | J47: 0.40202625 | K47: 0.4518938 | L47: 0.39576058 | M47: 0.41754988 | N47: 0.40865692 | O47: 0.4078901 | P47: 0.43453908 | R47: 0 | AF47: 0.40467718 | AT47: 0.31648597 | BH47: 0.36330248 | BV47: -0.83436364 | CJ47: #DIV/0!
D48: 0.093674487 | E48: 0.10555351 | F48: 0.098318361 | G48: 0.093960501 | H48: 0.074387117 | I48: 0.10116624 | J48: 0.083778113 | K48: 0.19892352 | L48: 0.083011907 | M48: 0.082687472 | N48: 0.082221268 | O48: 0.074128628 | P48: 0.13121993 | R48: 0 | AF48: 0.085057416 | AT48: 0.12435303 | BH48: 0.075661034 | BV48: 0.50677596 | CJ48: #DIV/0!
D49: 0.12821412 | E49: 0.14731769 | F49: 0.12829603 | G49: 0.13463902 | H49: 0.10967663 | I49: 0.12791632 | J49: 0.12070205 | K49: 0.075539805 | L49: 0.13056662 | M49: 0.13144314 | N49: 0.11199001 | O49: 0.11978122 | P49: 0.20985273 | R49: 0 | AF49: 0.11298562 | AT49: 0.14851607 | BH49: 0.087028547 | BV49: 1.1646389 | CJ49: #DIV/0!
D50: 0.17966192 | E50: 0.095259112 | F50: 0.14183906 | G50: 0.13415035 | H50: 0.21047234 | I50: 0.16341326 | J50: 0.20385736 | K50: 0.19428518 | L50: 0.18890892 | M50: 0.21035609 | N50: 0.22059194 | O50: 0.22010148 | P50: 0.10434569 | R50: 0 | AF50: 0.21406191 | AT50: 0.04361687 | BH50: 0.20887833 | BV50: -2.5057785 | CJ50: #DIV/0!
D51: 0.1630484 | E51: 0.074531524 | F51: 0.12469878 | G51: 0.11595484 | H51: 0.19568769 | I51: 0.14812161 | J51: 0.1901558 | K51: 0.15769415 | L51: 0.17430512 | M51: 0.19529648 | N51: 0.20724851 | O51: 0.20681248 | P51: 0.080727137 | R51: 0 | AF51: 0.18906749 | AT51: 0.04361687 | BH51: 0.20887833 | BV51: -2.5057785 | CJ51: #DIV/0!

Sheet Sälj
B1: Konto | C1: Namn | D1: Konto + namn | F1: 2601 | G1: 2602 | H1: 2603 | I1: 2604 | J1: 2605 | K1: 2606 | L1: 2607 | M1: 2608 | N1: 2609 | O1: 2610 | P1: 2611 | Q1: 2612 | R1: Summa 2026
B2: 5010 | C2: Lokalhyra | D2: 5010 Lokalhyra | R2: =SUM(F2:Q2) -> 0
B3: 5020 | C3: El för belysning | D3: 5020 El för belysning | R3: =SUM(F3:Q3) -> 0
B4: 5030 | C4: Värme | D4: 5030 Värme | R4: =SUM(F4:Q4) -> 0
B5: 5060 | C5: Städning | D5: 5060 Städning | R5: =SUM(F5:Q5) -> 0
B6: 5061 | C6: Renhållning | D6: 5061 Renhållning | R6: =SUM(F6:Q6) -> 0
B7: 5070 | C7: Reparation och underhåll av lokaler | D7: 5070 Reparation och underhåll av lokaler | R7: =SUM(F7:Q7) -> 0
B8: 5071 | C8: Anpassningar lokaler | D8: 5071 Anpassningar lokaler | R8: =SUM(F8:Q8) -> 0
B9: 5090 | C9: Övriga lokalkostnader | D9: 5090 Övriga lokalkostnader | R9: =SUM(F9:Q9) -> 0
B10: 5222 | C10: Leasing av inventarier och verktyg | D10: 5222 Leasing av inventarier och verktyg | R10: =SUM(F10:Q10) -> 0
B11: 5410 | C11: Förbrukningsinventarier | D11: 5410 Förbrukningsinventarier | R11: =SUM(F11:Q11) -> 0
B12: 5420 | C12: Dataprogram | D12: 5420 Dataprogram | R12: =SUM(F12:Q12) -> 0
B13: 5440 | C13: Förbrukningsemballage | D13: 5440 Förbrukningsemballage | R13: =SUM(F13:Q13) -> 0
... B19: 5466 | C19: Förbrukningsmaterial - Raptor | D19: 5466 Förbrukningsmaterial - Raptor | R19: =SUM(F19:Q19) -> 0
B20: 5480 | C20: Arbetskläder och skyddsmaterial | D20: 5480 Arbetskläder och skyddsmaterial | F20: 3 | G20: 3 | H20: 3 | I20: 3 | J20: 3 | K20: 3 | L20: 3 | M20: 3 | N20: 3 | O20: 3 | P20: 3 | Q20: 3 | R20: =SUM(F20:Q20) -> 36
B21: 5500 | C21: Reparation och underhåll (gruppkonto) | D21: 5500 Reparation och underhåll (gruppkonto) | R21: =SUM(F21:Q21) -> 0
B22: 5611 | C22: Drivmedel för Fordon/Maskiner | D22: 5611 Drivmedel för Fordon/Maskiner | R22: =SUM(F22:Q22) -> 0
B23: 5612 | C23: Försäkring och skatt för Fordon/Maskiner | D23: 5612 Försäkring och skatt för Fordon/Maskiner | F23: 2 | G23: 2 | H23: 2 | I23: 2 | J23: 2 | K23: 2 | L23: 2 | M23: 2 | N23: 2 | O23: 2 | P23: 2 | Q23: 2 | R23: =SUM(F23:Q23) -> 24
B24: 5613 | C24: Rep och underhåll av Fordon/Maskiner | D24: 5613 Rep och underhåll av Fordon/Maskiner | R24: =SUM(F24:Q24) -> 0
B25: 5615 | C25: Leasingavgifter för Fordon/Maskiner | D25: 5615 Leasingavgifter för Fordon/Maskiner | F25: 11 | G25: 11 | H25: 11 | I25: 11 | J25: 11 | K25: 11 | L25: 11 | M25: 11 | N25: 11 | O25: 11 | P25: 11 | Q25: 11 | R25: =SUM(F25:Q25) -> 132
B26: 5616 | C26: Trängselavgift, avdragsgill | D26: 5616 Trängselavgift, avdragsgill | R26: =SUM(F26:Q26) -> 0
B27: 5619 | C27: Övriga personbilskostnader | D27: 5619 Övriga personbilskostnader | R27: =SUM(F27:Q27) -> 0
B28: 5720 | C28: Tull- och speditionskostnader | D28: 5720 Tull- och speditionskostnader | R28: =SUM(F28:Q28) -> 0
B29: 5831 | C29: Kost och logi i Sverige | D29: 5831 Kost och logi i Sverige | R29: =SUM(F29:Q29) -> 0
B30: 5832 | C30: Kost och logi i utlandet | D30: 5832 Kost och logi i utlandet | F30: 25 | G30: 25 | H30: 25 | I30: 25 | J30: 25 | K30: 25 | L30: 25 | M30: 25 | N30: 25 | O30: 25 | P30: 25 | Q30: 25 | R30: =SUM(F30:Q30) -> 300 | T30: Tillväxt / business case
B31: 5890 | C31: Övriga resekostnader 25% | D31: 5890 Övriga resekostnader 25% | F31: 25 | G31: 25 | H31: 25 | I31: 25 | J31: 25 | K31: 25 | L31: 25 | M31: 25 | N31: 25 | O31: 25 | P31: 25 | Q31: 25 | R31: =SUM(F31:Q31) -> 300 | T31: Kundunderhåll
B32: 5891 | C32: Resekostnader i utlandet + flygbiljetter | D32: 5891 Resekostnader i utlandet + flygbiljetter | R32: =SUM(F32:Q32) -> 0
B33: 5892 | C33: Resekostnader 6% | D33: 5892 Resekostnader 6% | R33: =SUM(F33:Q33) -> 0
B34: 5900 | C34: Reklam och PR (gruppkonto) | D34: 5900 Reklam och PR (gruppkonto) | F34: =250/12 -> 20.833333 | G34: =250/12 -> 20.833333 | H34: =250/12 -> 20.833333 | I34: =250/12 -> 20.833333 | J34: =250/12 -> 20.833333 | K34: =250/12 -> 20.833333 | L34: =250/12 -> 20.833333 | M34: =250/12 -> 20.833333 | ... Q34: =250/12 -> 20.833333 | R34: =SUM(F34:Q34) -> 250 | T34: Tillväxt / business case
B35: 5930 | C35: Reklamtrycksaker och direktreklam | D35: 5930 Reklamtrycksaker och direktreklam | R35: =SUM(F35:Q35) -> 0
B36: 5940 | C36: Mässor o Utställningar | D36: 5940 Mässor o Utställningar | F36: =60/12 -> 5 | G36: =60/12 -> 5 | H36: =60/12 -> 5 | I36: =60/12 -> 5 | J36: =60/12 -> 5 | K36: =60/12 -> 5 | L36: =60/12 -> 5 | M36: =60/12 -> 5 | ... Q36: =60/12 -> 5 | R36: =SUM(F36:Q36) -> 60 | T36: Tillväxt / business case
B37: 5941 | C37: Kundaktiviteter /projektstyrt | D37: 5941 Kundaktiviteter /projektstyrt | R37: =SUM(F37:Q37) -> 0
B38: 5970 | C38: Film-, radio-, TV- och internetreklam | D38: 5970 Film-, radio-, TV- och internetreklam | R38: =SUM(F38:Q38) -> 0
B39: 5980 | C39: PR, inst. reklam och sponsring | D39: 5980 PR, inst. reklam och sponsring | R39: =SUM(F39:Q39) -> 0
B40: 5990 | C40: Övriga kostnader för reklam | D40: 5990 Övriga kostnader för reklam | R40: =SUM(F40:Q40) -> 0
B41: 6071 | C41: Representation, avdragsgill | D41: 6071 Representation, avdragsgill | F41: =150/12+6 -> 18.5 | G41: =150/12+6 -> 18.5 | H41: =150/12+6 -> 18.5 | I41: =150/12+6 -> 18.5 | J41: =150/12+6 -> 18.5 | K41: =150/12+6 -> 18.5 | L41: =150/12+6 -> 18.5 | M41: =150/12+6 -> 18.5 | ... Q41: =150/12+6 -> 18.5 | R41: =SUM(F41:Q41) -> 222 | T41: Löpande kundunderhåll
B42: 6072 | C42: Representation, ej avdragsgill | D42: 6072 Representation, ej avdragsgill | R42: =SUM(F42:Q42) -> 0
B43: 6090 | C43: Övriga försäljningskostnader | D43: 6090 Övriga försäljningskostnader | R43: =SUM(F43:Q43) -> 0 | T43: =SUM(R32:R41)/'[1]RR BU Koncern legal IC UVXair'!BH8 -> 0.0066624373
B44: 6091 | C44: Kundutbildning kostnad | D44: 6091 Kundutbildning kostnad | R44: =SUM(F44:Q44) -> 0
B45: 6092 | C45: Kundutbildning 12% | D45: 6092 Kundutbildning 12% | R45: =SUM(F45:Q45) -> 0
...

Sheet Produktion dir+lager
B1: Konto | C1: Namn | D1: Konto + namn | F1: 2601 | G1: 2602 | H1: 2603 | I1: 2604 | J1: 2605 | K1: 2606 | L1: 2607 | M1: 2608 | N1: 2609 | O1: 2610 | P1: 2611 | Q1: 2612 | R1: Summa 2026
B2: 5010 | C2: Lokalhyra | D2: 5010 Lokalhyra | R2: =SUM(F2:Q2) -> 0
B3: 5020 | C3: El för belysning | D3: 5020 El för belysning | R3: =SUM(F3:Q3) -> 0
B4: 5030 | C4: Värme | D4: 5030 Värme | R4: =SUM(F4:Q4) -> 0
B5: 5060 | C5: Städning | D5: 5060 Städning | R5: =SUM(F5:Q5) -> 0
B6: 5061 | C6: Renhållning | D6: 5061 Renhållning | R6: =SUM(F6:Q6) -> 0
B7: 5070 | C7: Reparation och underhåll av lokaler | D7: 5070 Reparation och underhåll av lokaler | R7: =SUM(F7:Q7) -> 0
B8: 5071 | C8: Anpassningar lokaler | D8: 5071 Anpassningar lokaler | R8: =SUM(F8:Q8) -> 0
B9: 5090 | C9: Övriga lokalkostnader | D9: 5090 Övriga lokalkostnader | R9: =SUM(F9:Q9) -> 0
B10: 5222 | C10: Leasing av inventarier och verktyg | D10: 5222 Leasing av inventarier och verktyg | R10: =SUM(F10:Q10) -> 0
B11: 5410 | C11: Förbrukningsinventarier | D11: 5410 Förbrukningsinventarier | R11: =SUM(F11:Q11) -> 0
B12: 5420 | C12: Dataprogram | D12: 5420 Dataprogram | R12: =SUM(F12:Q12) -> 0
B13: 5440 | C13: Förbrukningsemballage | D13: 5440 Förbrukningsemballage | R13: =SUM(F13:Q13) -> 0
B14: 5460 | C14: Förbrukningsmaterial | D14: 5460 Förbrukningsmaterial | F14: 20 | G14: 20 | H14: 20 | I14: 20 | J14: 20 | K14: 20 | L14: 20 | M14: 20 | N14: 20 | O14: 20 | P14: 20 | Q14: 20 | R14: =SUM(F14:Q14) -> 240
B15: 5462 | C15: Tes/Utveckl./prov förbrukning | D15: 5462 Tes/Utveckl./prov förbrukning | R15: =SUM(F15:Q15) -> 0
B16: 5463 | C16: Förbrukningsmaterial - verkstad | D16: 5463 Förbrukningsmaterial - verkstad | R16: =SUM(F16:Q16) -> 0
B17: 5464 | C17: Förbrukningsmtr/prov - svetsproduktion | D17: 5464 Förbrukningsmtr/prov - svetsproduktion | R17: =SUM(F17:Q17) -> 0
B18: 5465 | C18: Förbrukningsmaterial - kultillverkning | D18: 5465 Förbrukningsmaterial - kultillverkning | R18: =SUM(F18:Q18) -> 0
B19: 5466 | C19: Förbrukningsmaterial - Raptor | D19: 5466 Förbrukningsmaterial - Raptor | R19: =SUM(F19:Q19) -> 0
B20: 5480 | C20: Arbetskläder och skyddsmaterial | D20: 5480 Arbetskläder och skyddsmaterial | R20: =SUM(F20:Q20) -> 0
B21: 5500 | C21: Reparation och underhåll (gruppkonto) | D21: 5500 Reparation och underhåll (gruppkonto) | R21: =SUM(F21:Q21) -> 0
B22: 5611 | C22: Drivmedel för Fordon/Maskiner | D22: 5611 Drivmedel för Fordon/Maskiner | R22: =SUM(F22:Q22) -> 0
B23: 5612 | C23: Försäkring och skatt för Fordon/Maskiner | D23: 5612 Försäkring och skatt för Fordon/Maskiner | R23: =SUM(F23:Q23) -> 0
B24: 5613 | C24: Rep och underhåll av Fordon/Maskiner | D24: 5613 Rep och underhåll av Fordon/Maskiner | R24: =SUM(F24:Q24) -> 0
B25: 5615 | C25: Leasingavgifter för Fordon/Maskiner | D25: 5615 Leasingavgifter för Fordon/Maskiner | R25: =SUM(F25:Q25) -> 0
B26: 5616 | C26: Trängselavgift, avdragsgill | D26: 5616 Trängselavgift, avdragsgill | R26: =SUM(F26:Q26) -> 0
... B66: 6940 | C66: Kontroll-, provnings- och stämpelavgifter | D66: 6940 Kontroll-, provnings- och stämpelavgifter | R66: =SUM(F66:Q66) -> 0
B67: 6950 | C67: Tillsynsavgifter till myndigheter | D67: =B67 & C67 -> 6950Tillsynsavgifter till myndigheter | R67: =SUM(F67:Q67) -> 0
B68: 6970 | C68: Tidningar, tidskrifter och facklitteratur | D68: 6970 Tidningar, tidskrifter och facklitteratur | R68: =SUM(F68:Q68) -> 0
B69: 6981 | C69: Föreningsavgifter, avdragsgilla | D69: 6981 Föreningsavgifter, avdragsgilla | R69: =SUM(F69:Q69) -> 0
B70: 6982 | C70: Föreningsavgifter, ej avdragsgilla | D70: 6982 Föreningsavgifter, ej avdragsgilla | R70: =SUM(F70:Q70) -> 0
B71: 6991 | C71: Övriga externa kostnader, avdragsgilla | D71: 6991 Övriga externa kostnader, avdragsgilla | R71: =SUM(F71:Q71) -> 0
B72: 6992 | C72: Övriga externa kostnader, ej avdragsgilla | D72: 6992 Övriga externa kostnader, ej avdragsgilla | R72: =SUM(F72:Q72) -> 0
B73: 7010 | C73: Löner kollektivanställda 1947-1985 (2012) | D73: 7010 Löner kollektivanställda 1947-1985 (2012) | R73: =SUM(F73:Q73) -> 0
B74: 7019 | C74: Upplupna löner | D74: 7019 Upplupna löner | R74: =SUM(F74:Q74) -> 0
B75: 7090 | C75: Förändring av semesterlöneskuld | D75: 7090 Förändring av semesterlöneskuld | R75: =SUM(F75:Q75) -> 0
B76: 7210 | C76: Löner till tjänstemän födda 1947-1985 (2012) | D76: 7210 Löner till tjänstemän födda 1947-1985 (2012) | F76: =41.5+38+25 -> 104.5 | G76: =41.5+38+25 -> 104.5 | H76: =41.5+38+25 -> 104.5 | I76: =(41.5+38+25)*1.03 -> 107.635 | J76: =(41.5+38+25)*1.03 -> 107.635 | K76: =(41.5+38+25)*1.03 -> 107.635 | L76: =(41.5+38+25)*1.03 -> 107.635 | M76: =(41.5+38+25)*1.03 -> 107.635 | N76: =(41.5+38+25)*1.03 -> 107.635 | O76: =(41.5+38+25)*1.03 -> 107.635 | P76: =(41.5+38+25)*1.03 -> 107.635 | Q76: =(41.5+38+25)*1.03 -> 107.635 | R76: =SUM(F76:Q76) -> 1282.215
B77: 7220 | C77: Löner till företagsledare | D77: 7220 Löner till företagsledare | R77: =SUM(F77:Q77) -> 0
B78: 7280 | C78: Sjuklön | D78: 7280 Sjuklön | R78: =SUM(F78:Q78) -> 0
B79: 7282 | C79: Semestertillägg 0,8 % | D79: 7282 Semestertillägg 0,8 % | F79: =F76*0.008 -> 0.836 | G79: =G76*0.008 -> 0.836 | H79: =H76*0.008 -> 0.836 | I79: =I76*0.008 -> 0.86108 | J79: =J76*0.008 -> 0.86108 | K79: =K76*0.008 -> 0.86108 | L79: =L76*0.008 -> 0.86108 | M79: =M76*0.008 -> 0.86108 | ... Q79: =Q76*0.008 -> 0.86108 | R79: =SUM(F79:Q79) -> 10.25772
...

Sheet Produktion OH 
B1: Konto | C1: Namn | D1: Konto + namn | F1: 2601 | G1: 2602 | H1: 2603 | I1: 2604 | J1: 2605 | K1: 2606 | L1: 2607 | M1: 2608 | N1: 2609 | O1: 2610 | P1: 2611 | Q1: 2612 | R1: Summa 2026 | U1: Kominerat med ny lokal | V1: 2601 | W1: 2602 | X1: 2603 | Y1: 2604 | Z1: 2605 | AA1: 2606 | AB1: 2607 | AC1: 2608 | AD1: 2609 | AE1: 2610 | AF1: 2611 | AG1: 2612
B2: 5010 | C2: Lokalhyra | D2: 5010 Lokalhyra | F2: 45 | G2: 45 | H2: 45 | I2: 45 | J2: 45 | K2: 45 | L2: 45 | M2: 45 | N2: 45 | O2: 45 | P2: 45 | Q2: 45 | R2: =SUM(F2:Q2) -> 540 | V2: =F2+'Ny lokal'!F2 -> 45 | W2: =G2+'Ny lokal'!G2 -> 45 | X2: =H2+'Ny lokal'!H2 -> 45 | Y2: =I2+'Ny lokal'!I2 -> 45 | Z2: =J2+'Ny lokal'!J2 -> 45 | AA2: =K2+'Ny lokal'!K2 -> 65.833333 | AB2: =L2+'Ny lokal'!L2 -> 65.833333 | AC2: =M2+'Ny lokal'!M2 -> 65.833333 | ... AG2: =Q2+'Ny lokal'!Q2 -> 65.833333
B3: 5020 | C3: El för belysning | D3: 5020 El för belysning | R3: =SUM(F3:Q3) -> 0 | V3: =F3+'Ny lokal'!F3 -> 0 | W3: =G3+'Ny lokal'!G3 -> 0 | X3: =H3+'Ny lokal'!H3 -> 0 | Y3: =I3+'Ny lokal'!I3 -> 0 | Z3: =J3+'Ny lokal'!J3 -> 0 | AA3: =K3+'Ny lokal'!K3 -> 0 | AB3: =L3+'Ny lokal'!L3 -> 0 | AC3: =M3+'Ny lokal'!M3 -> 0 | ... AG3: =Q3+'Ny lokal'!Q3 -> 0
B4: 5030 | C4: Värme | D4: 5030 Värme | R4: =SUM(F4:Q4) -> 0 | V4: =F4+'Ny lokal'!F4 -> 0 | W4: =G4+'Ny lokal'!G4 -> 0 | X4: =H4+'Ny lokal'!H4 -> 0 | Y4: =I4+'Ny lokal'!I4 -> 0 | Z4: =J4+'Ny lokal'!J4 -> 0 | AA4: =K4+'Ny lokal'!K4 -> 8.75 | AB4: =L4+'Ny lokal'!L4 -> 8.75 | AC4: =M4+'Ny lokal'!M4 -> 8.75 | ... AG4: =Q4+'Ny lokal'!Q4 -> 8.75
B5: 5060 | C5: Städning | D5: 5060 Städning | F5: 6 | G5: 6 | H5: 6 | I5: 6 | J5: 6 | K5: 6 | L5: 6 | M5: 6 | N5: 6 | O5: 6 | P5: 6 | Q5: 6 | R5: =SUM(F5:Q5) -> 72 | V5: =F5+'Ny lokal'!F5 -> 6 | W5: =G5+'Ny lokal'!G5 -> 6 | X5: =H5+'Ny lokal'!H5 -> 6 | Y5: =I5+'Ny lokal'!I5 -> 6 | Z5: =J5+'Ny lokal'!J5 -> 6 | AA5: =K5+'Ny lokal'!K5 -> 6 | AB5: =L5+'Ny lokal'!L5 -> 6 | AC5: =M5+'Ny lokal'!M5 -> 6 | ... AG5: =Q5+'Ny lokal'!Q5 -> 6
B6: 5061 | C6: Renhållning | D6: 5061 Renhållning | R6: =SUM(F6:Q6) -> 0 | V6: =F6+'Ny lokal'!F6 -> 0 | W6: =G6+'Ny lokal'!G6 -> 0 | X6: =H6+'Ny lokal'!H6 -> 0 | Y6: =I6+'Ny lokal'!I6 -> 0 | Z6: =J6+'Ny lokal'!J6 -> 0 | AA6: =K6+'Ny lokal'!K6 -> 0 | AB6: =L6+'Ny lokal'!L6 -> 0 | AC6: =M6+'Ny lokal'!M6 -> 0 | ... AG6: =Q6+'Ny lokal'!Q6 -> 0
B7: 5070 | C7: Reparation och underhåll av lokaler | D7: 5070 Reparation och underhåll av lokaler | R7: =SUM(F7:Q7) -> 0 | V7: =F7+'Ny lokal'!F7 -> 0 | W7: =G7+'Ny lokal'!G7 -> 0 | X7: =H7+'Ny lokal'!H7 -> 0 | Y7: =I7+'Ny lokal'!I7 -> 0 | Z7: =J7+'Ny lokal'!J7 -> 0 | AA7: =K7+'Ny lokal'!K7 -> 0 | AB7: =L7+'Ny lokal'!L7 -> 0 | AC7: =M7+'Ny lokal'!M7 -> 0 | ... AG7: =Q7+'Ny lokal'!Q7 -> 0
B8: 5071 | C8: Anpassningar lokaler | D8: 5071 Anpassningar lokaler | R8: =SUM(F8:Q8) -> 0 | V8: =F8+'Ny lokal'!F8 -> 0 | W8: =G8+'Ny lokal'!G8 -> 0 | X8: =H8+'Ny lokal'!H8 -> 0 | Y8: =I8+'Ny lokal'!I8 -> 0 | Z8: =J8+'Ny lokal'!J8 -> 0 | AA8: =K8+'Ny lokal'!K8 -> 0 | AB8: =L8+'Ny lokal'!L8 -> 0 | AC8: =M8+'Ny lokal'!M8 -> 0 | ... AG8: =Q8+'Ny lokal'!Q8 -> 0
B9: 5090 | C9: Övriga lokalkostnader | D9: 5090 Övriga lokalkostnader | R9: =SUM(F9:Q9) -> 0 | V9: =F9+'Ny lokal'!F9 -> 0 | W9: =G9+'Ny lokal'!G9 -> 0 | X9: =H9+'Ny lokal'!H9 -> 0 | Y9: =I9+'Ny lokal'!I9 -> 0 | Z9: =J9+'Ny lokal'!J9 -> 0 | AA9: =K9+'Ny lokal'!K9 -> 200 | AB9: =L9+'Ny lokal'!L9 -> 18.083333 | AC9: =M9+'Ny lokal'!M9 -> 18.083333 | ... AG9: =Q9+'Ny lokal'!Q9 -> 18.083333
B10: 5222 | C10: Leasing av inventarier och verktyg | D10: 5222 Leasing av inventarier och verktyg | F10: 5 | G10: 5 | H10: 5 | I10: 5 | J10: 5 | K10: 5 | L10: 5 | M10: 5 | N10: 5 | O10: 5 | P10: 5 | Q10: 5 | R10: =SUM(F10:Q10) -> 60 | S10: Hyra container | V10: =F10+'Ny lokal'!F10 -> 5 | W10: =G10+'Ny lokal'!G10 -> 5 | X10: =H10+'Ny lokal'!H10 -> 5 | Y10: =I10+'Ny lokal'!I10 -> 5 | Z10: =J10+'Ny lokal'!J10 -> 5 | AA10: =K10+'Ny lokal'!K10 -> 5 | AB10: =L10+'Ny lokal'!L10 -> 5 | AC10: =M10+'Ny lokal'!M10 -> 5 | ... AG10: =Q10+'Ny lokal'!Q10 -> 5
B11: 5410 | C11: Förbrukningsinventarier | D11: 5410 Förbrukningsinventarier | F11: 5 | G11: 5 | H11: 5 | I11: 5 | J11: 5 | K11: 5 | L11: 5 | M11: 5 | N11: 5 | O11: 5 | P11: 5 | Q11: 5 | R11: =SUM(F11:Q11) -> 60 | V11: =F11+'Ny lokal'!F11 -> 5 | W11: =G11+'Ny lokal'!G11 -> 5 | X11: =H11+'Ny lokal'!H11 -> 5 | Y11: =I11+'Ny lokal'!I11 -> 5 | Z11: =J11+'Ny lokal'!J11 -> 5 | AA11: =K11+'Ny lokal'!K11 -> 5 | AB11: =L11+'Ny lokal'!L11 -> 5 | AC11: =M11+'Ny lokal'!M11 -> 5 | ... AG11: =Q11+'Ny lokal'!Q11 -> 5
B12: 5420 | C12: Dataprogram | D12: 5420 Dataprogram | R12: =SUM(F12:Q12) -> 0 | V12: =F12+'Ny lokal'!F12 -> 0 | W12: =G12+'Ny lokal'!G12 -> 0 | X12: =H12+'Ny lokal'!H12 -> 0 | Y12: =I12+'Ny lokal'!I12 -> 0 | Z12: =J12+'Ny lokal'!J12 -> 0 | AA12: =K12+'Ny lokal'!K12 -> 0 | AB12: =L12+'Ny lokal'!L12 -> 0 | AC12: =M12+'Ny lokal'!M12 -> 0 | ... AG12: =Q12+'Ny lokal'!Q12 -> 0
B13: 5440 | C13: Förbrukningsemballage | D13: 5440 Förbrukningsemballage | R13: =SUM(F13:Q13) -> 0 | V13: =F13+'Ny lokal'!F13 -> 0 | W13: =G13+'Ny lokal'!G13 -> 0 | X13: =H13+'Ny lokal'!H13 -> 0 | Y13: =I13+'Ny lokal'!I13 -> 0 | Z13: =J13+'Ny lokal'!J13 -> 0 | AA13: =K13+'Ny lokal'!K13 -> 0 | AB13: =L13+'Ny lokal'!L13 -> 0 | AC13: =M13+'Ny lokal'!M13 -> 0 | ... AG13: =Q13+'Ny lokal'!Q13 -> 0
B14: 5460 | C14: Förbrukningsmaterial | D14: 5460 Förbrukningsmaterial | R14: =SUM(F14:Q14) -> 0 | V14: =F14+'Ny lokal'!F14 -> 0 | W14: =G14+'Ny lokal'!G14 -> 0 | X14: =H14+'Ny lokal'!H14 -> 0 | Y14: =I14+'Ny lokal'!I14 -> 0 | Z14: =J14+'Ny lokal'!J14 -> 0 | AA14: =K14+'Ny lokal'!K14 -> 0 | AB14: =L14+'Ny lokal'!L14 -> 0 | AC14: =M14+'Ny lokal'!M14 -> 0 | ... AG14: =Q14+'Ny lokal'!Q14 -> 0
B15: 5462 | C15: Tes/Utveckl./prov förbrukning | D15: 5462 Tes/Utveckl./prov förbrukning | R15: =SUM(F15:Q15) -> 0 | V15: =F15+'Ny lokal'!F15 -> 0 | W15: =G15+'Ny lokal'!G15 -> 0 | X15: =H15+'Ny lokal'!H15 -> 0 | Y15: =I15+'Ny lokal'!I15 -> 0 | Z15: =J15+'Ny lokal'!J15 -> 0 | AA15: =K15+'Ny lokal'!K15 -> 0 | AB15: =L15+'Ny lokal'!L15 -> 0 | AC15: =M15+'Ny lokal'!M15 -> 0 | ... AG15: =Q15+'Ny lokal'!Q15 -> 0
B16: 5463 | C16: Förbrukningsmaterial - verkstad | D16: 5463 Förbrukningsmaterial - verkstad | R16: =SUM(F16:Q16) -> 0 | V16: =F16+'Ny lokal'!F16 -> 0 | W16: =G16+'Ny lokal'!G16 -> 0 | X16: =H16+'Ny lokal'!H16 -> 0 | Y16: =I16+'Ny lokal'!I16 -> 0 | Z16: =J16+'Ny lokal'!J16 -> 0 | AA16: =K16+'Ny lokal'!K16 -> 0 | AB16: =L16+'Ny lokal'!L16 -> 0 | AC16: =M16+'Ny lokal'!M16 -> 0 | ... AG16: =Q16+'Ny lokal'!Q16 -> 0
B17: 5464 | C17: Förbrukningsmtr/prov - svetsproduktion | D17: 5464 Förbrukningsmtr/prov - svetsproduktion | R17: =SUM(F17:Q17) -> 0 | V17: =F17+'Ny lokal'!F17 -> 0 | W17: =G17+'Ny lokal'!G17 -> 0 | X17: =H17+'Ny lokal'!H17 -> 0 | Y17: =I17+'Ny lokal'!I17 -> 0 | Z17: =J17+'Ny lokal'!J17 -> 0 | AA17: =K17+'Ny lokal'!K17 -> 0 | AB17: =L17+'Ny lokal'!L17 -> 0 | AC17: =M17+'Ny lokal'!M17 -> 0 | ... AG17: =Q17+'Ny lokal'!Q17 -> 0
B18: 5465 | C18: Förbrukningsmaterial - kultillverkning | D18: 5465 Förbrukningsmaterial - kultillverkning | R18: =SUM(F18:Q18) -> 0 | V18: =F18+'Ny lokal'!F18 -> 0 | W18: =G18+'Ny lokal'!G18 -> 0 | X18: =H18+'Ny lokal'!H18 -> 0 | Y18: =I18+'Ny lokal'!I18 -> 0 | Z18: =J18+'Ny lokal'!J18 -> 0 | AA18: =K18+'Ny lokal'!K18 -> 0 | AB18: =L18+'Ny lokal'!L18 -> 0 | AC18: =M18+'Ny lokal'!M18 -> 0 | ... AG18: =Q18+'Ny lokal'!Q18 -> 0
B19: 5466 | C19: Förbrukningsmaterial - Raptor | D19: 5466 Förbrukningsmaterial - Raptor | R19: =SUM(F19:Q19) -> 0 | V19: =F19+'Ny lokal'!F19 -> 0 | W19: =G19+'Ny lokal'!G19 -> 0 | X19: =H19+'Ny lokal'!H19 -> 0 | Y19: =I19+'Ny lokal'!I19 -> 0 | Z19: =J19+'Ny lokal'!J19 -> 0 | AA19: =K19+'Ny lokal'!K19 -> 0 | AB19: =L19+'Ny lokal'!L19 -> 0 | AC19: =M19+'Ny lokal'!M19 -> 0 | ... AG19: =Q19+'Ny lokal'!Q19 -> 0
B20: 5480 | C20: Arbetskläder och skyddsmaterial | D20: 5480 Arbetskläder och skyddsmaterial | F20: =2*6/12 -> 1 | G20: =2*6/12 -> 1 | H20: =2*6/12 -> 1 | I20: =2*6/12 -> 1 | J20: =2*6/12 -> 1 | K20: =2*6/12 -> 1 | L20: =2*6/12 -> 1 | M20: =2*6/12 -> 1 | ... Q20: =2*6/12 -> 1 | R20: =SUM(F20:Q20) -> 12 | V20: =F20+'Ny lokal'!F20 -> 1 | W20: =G20+'Ny lokal'!G20 -> 1 | X20: =H20+'Ny lokal'!H20 -> 1 | Y20: =I20+'Ny lokal'!I20 -> 1 | Z20: =J20+'Ny lokal'!J20 -> 1 | AA20: =K20+'Ny lokal'!K20 -> 1 | AB20: =L20+'Ny lokal'!L20 -> 1 | AC20: =M20+'Ny lokal'!M20 -> 1 | ... AG20: =Q20+'Ny lokal'!Q20 -> 1
B21: 5500 | C21: Reparation och underhåll (gruppkonto) | D21: 5500 Reparation och underhåll (gruppkonto) | R21: =SUM(F21:Q21) -> 0 | V21: =F21+'Ny lokal'!F21 -> 0 | W21: =G21+'Ny lokal'!G21 -> 0 | X21: =H21+'Ny lokal'!H21 -> 0 | Y21: =I21+'Ny lokal'!I21 -> 0 | Z21: =J21+'Ny lokal'!J21 -> 0 | AA21: =K21+'Ny lokal'!K21 -> 0 | AB21: =L21+'Ny lokal'!L21 -> 0 | AC21: =M21+'Ny lokal'!M21 -> 0 | ... AG21: =Q21+'Ny lokal'!Q21 -> 0
B22: 5611 | C22: Drivmedel för Fordon/Maskiner | D22: 5611 Drivmedel för Fordon/Maskiner | F22: =50/12 -> 4.1666667 | G22: =50/12 -> 4.1666667 | H22: =50/12 -> 4.1666667 | I22: =50/12 -> 4.1666667 | J22: =50/12 -> 4.1666667 | K22: =50/12 -> 4.1666667 | L22: =50/12 -> 4.1666667 | M22: =50/12 -> 4.1666667 | ... Q22: =50/12 -> 4.1666667 | R22: =SUM(F22:Q22) -> 50 | V22: =F22+'Ny lokal'!F22 -> 4.1666667 | W22: =G22+'Ny lokal'!G22 -> 4.1666667 | X22: =H22+'Ny lokal'!H22 -> 4.1666667 | Y22: =I22+'Ny lokal'!I22 -> 4.1666667 | Z22: =J22+'Ny lokal'!J22 -> 4.1666667 | AA22: =K22+'Ny lokal'!K22 -> 4.1666667 | AB22: =L22+'Ny lokal'!L22 -> 4.1666667 | AC22: =M22+'Ny lokal'!M22 -> 4.1666667 | ... AG22: =Q22+'Ny lokal'!Q22 -> 4.1666667
B23: 5612 | C23: Försäkring och skatt för Fordon/Maskiner | D23: 5612 Försäkring och skatt för Fordon/Maskiner | F23: =50/12 -> 4.1666667 | G23: =50/12 -> 4.1666667 | H23: =50/12 -> 4.1666667 | I23: =50/12 -> 4.1666667 | J23: =50/12 -> 4.1666667 | K23: =50/12 -> 4.1666667 | L23: =50/12 -> 4.1666667 | M23: =50/12 -> 4.1666667 | ... Q23: =50/12 -> 4.1666667 | R23: =SUM(F23:Q23) -> 50 | V23: =F23+'Ny lokal'!F23 -> 4.1666667 | W23: =G23+'Ny lokal'!G23 -> 4.1666667 | X23: =H23+'Ny lokal'!H23 -> 4.1666667 | Y23: =I23+'Ny lokal'!I23 -> 4.1666667 | Z23: =J23+'Ny lokal'!J23 -> 4.1666667 | AA23: =K23+'Ny lokal'!K23 -> 4.1666667 | AB23: =L23+'Ny lokal'!L23 -> 4.1666667 | AC23: =M23+'Ny lokal'!M23 -> 4.1666667 | ... AG23: =Q23+'Ny lokal'!Q23 -> 4.1666667
B24: 5613 | C24: Rep och underhåll av Fordon/Maskiner | D24: 5613 Rep och underhåll av Fordon/Maskiner | R24: =SUM(F24:Q24) -> 0 | V24: =F24+'Ny lokal'!F24 -> 0 | W24: =G24+'Ny lokal'!G24 -> 0 | X24: =H24+'Ny lokal'!H24 -> 0 | Y24: =I24+'Ny lokal'!I24 -> 0 | Z24: =J24+'Ny lokal'!J24 -> 0 | AA24: =K24+'Ny lokal'!K24 -> 0 | AB24: =L24+'Ny lokal'!L24 -> 0 | AC24: =M24+'Ny lokal'!M24 -> 0 | ... AG24: =Q24+'Ny lokal'!Q24 -> 0
B25: 5615 | C25: Leasingavgifter för Fordon/Maskiner | D25: 5615 Leasingavgifter för Fordon/Maskiner | R25: =SUM(F25:Q25) -> 0 | V25: =F25+'Ny lokal'!F25 -> 0 | W25: =G25+'Ny lokal'!G25 -> 0 | X25: =H25+'Ny lokal'!H25 -> 0 | Y25: =I25+'Ny lokal'!I25 -> 0 | Z25: =J25+'Ny lokal'!J25 -> 0 | AA25: =K25+'Ny lokal'!K25 -> 0 | AB25: =L25+'Ny lokal'!L25 -> 0 | AC25: =M25+'Ny lokal'!M25 -> 0 | ... AG25: =Q25+'Ny lokal'!Q25 -> 0
B26: 5616 | C26: Trängselavgift, avdragsgill | D26: 5616 Trängselavgift, avdragsgill | R26: =SUM(F26:Q26) -> 0 | V26: =F26+'Ny lokal'!F26 -> 0 | W26: =G26+'Ny lokal'!G26 -> 0 | X26: =H26+'Ny lokal'!H26 -> 0 | Y26: =I26+'Ny lokal'!I26 -> 0 | Z26: =J26+'Ny lokal'!J26 -> 0 | AA26: =K26+'Ny lokal'!K26 -> 0 | AB26: =L26+'Ny lokal'!L26 -> 0 | AC26: =M26+'Ny lokal'!M26 -> 0 | ... AG26: =Q26+'Ny lokal'!Q26 -> 0
B27: 5619 | C27: Övriga personbilskostnader | D27: 5619 Övriga personbilskostnader | F27: =30/12 -> 2.5 | G27: =30/12 -> 2.5 | H27: =30/12 -> 2.5 | I27: =30/12 -> 2.5 | J27: =30/12 -> 2.5 | K27: =30/12 -> 2.5 | L27: =30/12 -> 2.5 | M27: =30/12 -> 2.5 | ... Q27: =30/12 -> 2.5 | R27: =SUM(F27:Q27) -> 30 | V27: =F27+'Ny lokal'!F27 -> 2.5 | W27: =G27+'Ny lokal'!G27 -> 2.5 | X27: =H27+'Ny lokal'!H27 -> 2.5 | Y27: =I27+'Ny lokal'!I27 -> 2.5 | Z27: =J27+'Ny lokal'!J27 -> 2.5 | AA27: =K27+'Ny lokal'!K27 -> 2.5 | AB27: =L27+'Ny lokal'!L27 -> 2.5 | AC27: =M27+'Ny lokal'!M27 -> 2.5 | ... AG27: =Q27+'Ny lokal'!Q27 -> 2.5
B28: 5720 | C28: Tull- och speditionskostnader | D28: 5720 Tull- och speditionskostnader | R28: =SUM(F28:Q28) -> 0 | V28: =F28+'Ny lokal'!F28 -> 0 | W28: =G28+'Ny lokal'!G28 -> 0 | X28: =H28+'Ny lokal'!H28 -> 0 | Y28: =I28+'Ny lokal'!I28 -> 0 | Z28: =J28+'Ny lokal'!J28 -> 0 | AA28: =K28+'Ny lokal'!K28 -> 0 | AB28: =L28+'Ny lokal'!L28 -> 0 | AC28: =M28+'Ny lokal'!M28 -> 0 | ... AG28: =Q28+'Ny lokal'!Q28 -> 0
B29: 5831 | C29: Kost och logi i Sverige | D29: 5831 Kost och logi i Sverige | R29: =SUM(F29:Q29) -> 0 | V29: =F29+'Ny lokal'!F29 -> 0 | W29: =G29+'Ny lokal'!G29 -> 0 | X29: =H29+'Ny lokal'!H29 -> 0 | Y29: =I29+'Ny lokal'!I29 -> 0 | Z29: =J29+'Ny lokal'!J29 -> 0 | AA29: =K29+'Ny lokal'!K29 -> 0 | AB29: =L29+'Ny lokal'!L29 -> 0 | AC29: =M29+'Ny lokal'!M29 -> 0 | ... AG29: =Q29+'Ny lokal'!Q29 -> 0
B30: 5832 | C30: Kost och logi i utlandet | D30: 5832 Kost och logi i utlandet | R30: =SUM(F30:Q30) -> 0 | V30: =F30+'Ny lokal'!F30 -> 0 | W30: =G30+'Ny lokal'!G30 -> 0 | X30: =H30+'Ny lokal'!H30 -> 0 | Y30: =I30+'Ny lokal'!I30 -> 0 | Z30: =J30+'Ny lokal'!J30 -> 0 | AA30: =K30+'Ny lokal'!K30 -> 0 | AB30: =L30+'Ny lokal'!L30 -> 0 | AC30: =M30+'Ny lokal'!M30 -> 0 | ... AG30: =Q30+'Ny lokal'!Q30 -> 0
B31: 5890 | C31: Övriga resekostnader 25% | D31: 5890 Övriga resekostnader 25% | R31: =SUM(F31:Q31) -> 0 | V31: =F31+'Ny lokal'!F31 -> 0 | W31: =G31+'Ny lokal'!G31 -> 0 | X31: =H31+'Ny lokal'!H31 -> 0 | Y31: =I31+'Ny lokal'!I31 -> 0 | Z31: =J31+'Ny lokal'!J31 -> 0 | AA31: =K31+'Ny lokal'!K31 -> 0 | AB31: =L31+'Ny lokal'!L31 -> 0 | AC31: =M31+'Ny lokal'!M31 -> 0 | ... AG31: =Q31+'Ny lokal'!Q31 -> 0
B32: 5891 | C32: Resekostnader i utlandet + flygbiljetter | D32: 5891 Resekostnader i utlandet + flygbiljetter | R32: =SUM(F32:Q32) -> 0 | V32: =F32+'Ny lokal'!F32 -> 0 | W32: =G32+'Ny lokal'!G32 -> 0 | X32: =H32+'Ny lokal'!H32 -> 0 | Y32: =I32+'Ny lokal'!I32 -> 0 | Z32: =J32+'Ny lokal'!J32 -> 0 | AA32: =K32+'Ny lokal'!K32 -> 0 | AB32: =L32+'Ny lokal'!L32 -> 0 | AC32: =M32+'Ny lokal'!M32 -> 0 | ... AG32: =Q32+'Ny lokal'!Q32 -> 0
B33: 5892 | C33: Resekostnader 6% | D33: 5892 Resekostnader 6% | R33: =SUM(F33:Q33) -> 0 | V33: =F33+'Ny lokal'!F33 -> 0 | W33: =G33+'Ny lokal'!G33 -> 0 | X33: =H33+'Ny lokal'!H33 -> 0 | Y33: =I33+'Ny lokal'!I33 -> 0 | Z33: =J33+'Ny lokal'!J33 -> 0 | AA33: =K33+'Ny lokal'!K33 -> 0 | AB33: =L33+'Ny lokal'!L33 -> 0 | AC33: =M33+'Ny lokal'!M33 -> 0 | ... AG33: =Q33+'Ny lokal'!Q33 -> 0
B34: 5900 | C34: Reklam och PR (gruppkonto) | D34: 5900 Reklam och PR (gruppkonto) | R34: =SUM(F34:Q34) -> 0 | V34: =F34+'Ny lokal'!F34 -> 0 | W34: =G34+'Ny lokal'!G34 -> 0 | X34: =H34+'Ny lokal'!H34 -> 0 | Y34: =I34+'Ny lokal'!I34 -> 0 | Z34: =J34+'Ny lokal'!J34 -> 0 | AA34: =K34+'Ny lokal'!K34 -> 0 | AB34: =L34+'Ny lokal'!L34 -> 0 | AC34: =M34+'Ny lokal'!M34 -> 0 | ... AG34: =Q34+'Ny lokal'!Q34 -> 0
B35: 5930 | C35: Reklamtrycksaker och direktreklam | D35: 5930 Reklamtrycksaker och direktreklam | R35: =SUM(F35:Q35) -> 0 | V35: =F35+'Ny lokal'!F35 -> 0 | W35: =G35+'Ny lokal'!G35 -> 0 | X35: =H35+'Ny lokal'!H35 -> 0 | Y35: =I35+'Ny lokal'!I35 -> 0 | Z35: =J35+'Ny lokal'!J35 -> 0 | AA35: =K35+'Ny lokal'!K35 -> 0 | AB35: =L35+'Ny lokal'!L35 -> 0 | AC35: =M35+'Ny lokal'!M35 -> 0 | ... AG35: =Q35+'Ny lokal'!Q35 -> 0
B36: 5940 | C36: Mässor o Utställningar | D36: 5940 Mässor o Utställningar | R36: =SUM(F36:Q36) -> 0 | V36: =F36+'Ny lokal'!F36 -> 0 | W36: =G36+'Ny lokal'!G36 -> 0 | X36: =H36+'Ny lokal'!H36 -> 0 | Y36: =I36+'Ny lokal'!I36 -> 0 | Z36: =J36+'Ny lokal'!J36 -> 0 | AA36: =K36+'Ny lokal'!K36 -> 0 | AB36: =L36+'Ny lokal'!L36 -> 0 | AC36: =M36+'Ny lokal'!M36 -> 0 | ... AG36: =Q36+'Ny lokal'!Q36 -> 0
B37: 5941 | C37: Kundaktiviteter /projektstyrt | D37: 5941 Kundaktiviteter /projektstyrt | R37: =SUM(F37:Q37) -> 0 | V37: =F37+'Ny lokal'!F37 -> 0 | W37: =G37+'Ny lokal'!G37 -> 0 | X37: =H37+'Ny lokal'!H37 -> 0 | Y37: =I37+'Ny lokal'!I37 -> 0 | Z37: =J37+'Ny lokal'!J37 -> 0 | AA37: =K37+'Ny lokal'!K37 -> 0 | AB37: =L37+'Ny lokal'!L37 -> 0 | AC37: =M37+'Ny lokal'!M37 -> 0 | ... AG37: =Q37+'Ny lokal'!Q37 -> 0
B38: 5970 | C38: Film-, radio-, TV- och internetreklam | D38: 5970 Film-, radio-, TV- och internetreklam | R38: =SUM(F38:Q38) -> 0 | V38: =F38+'Ny lokal'!F38 -> 0 | W38: =G38+'Ny lokal'!G38 -> 0 | X38: =H38+'Ny lokal'!H38 -> 0 | Y38: =I38+'Ny lokal'!I38 -> 0 | Z38: =J38+'Ny lokal'!J38 -> 0 | AA38: =K38+'Ny lokal'!K38 -> 0 | AB38: =L38+'Ny lokal'!L38 -> 0 | AC38: =M38+'Ny lokal'!M38 -> 0 | ... AG38: =Q38+'Ny lokal'!Q38 -> 0
B39: 5980 | C39: PR, inst. reklam och sponsring | D39: 5980 PR, inst. reklam och sponsring | R39: =SUM(F39:Q39) -> 0 | V39: =F39+'Ny lokal'!F39 -> 0 | W39: =G39+'Ny lokal'!G39 -> 0 | X39: =H39+'Ny lokal'!H39 -> 0 | Y39: =I39+'Ny lokal'!I39 -> 0 | Z39: =J39+'Ny lokal'!J39 -> 0 | AA39: =K39+'Ny lokal'!K39 -> 0 | AB39: =L39+'Ny lokal'!L39 -> 0 | AC39: =M39+'Ny lokal'!M39 -> 0 | ... AG39: =Q39+'Ny lokal'!Q39 -> 0
B40: 5990 | C40: Övriga kostnader för reklam | D40: 5990 Övriga kostnader för reklam | R40: =SUM(F40:Q40) -> 0 | V40: =F40+'Ny lokal'!F40 -> 0 | W40: =G40+'Ny lokal'!G40 -> 0 | X40: =H40+'Ny lokal'!H40 -> 0 | Y40: =I40+'Ny lokal'!I40 -> 0 | Z40: =J40+'Ny lokal'!J40 -> 0 | AA40: =K40+'Ny lokal'!K40 -> 0 | AB40: =L40+'Ny lokal'!L40 -> 0 | AC40: =M40+'Ny lokal'!M40 -> 0 | ... AG40: =Q40+'Ny lokal'!Q40 -> 0
...

Sheet Produktutveckling
B1: Konto | C1: Namn | D1: Konto + namn | F1: 2601 | G1: 2602 | H1: 2603 | I1: 2604 | J1: 2605 | K1: 2606 | L1: 2607 | M1: 2608 | N1: 2609 | O1: 2610 | P1: 2611 | Q1: 2612 | R1: Summa 2026
B2: 5010 | C2: Lokalhyra | D2: 5010 Lokalhyra | R2: =SUM(F2:Q2) -> 0
B3: 5020 | C3: El för belysning | D3: 5020 El för belysning | R3: =SUM(F3:Q3) -> 0
B4: 5030 | C4: Värme | D4: 5030 Värme | R4: =SUM(F4:Q4) -> 0
B5: 5060 | C5: Städning | D5: 5060 Städning | R5: =SUM(F5:Q5) -> 0
B6: 5061 | C6: Renhållning | D6: 5061 Renhållning | R6: =SUM(F6:Q6) -> 0
B7: 5070 | C7: Reparation och underhåll av lokaler | D7: 5070 Reparation och underhåll av lokaler | R7: =SUM(F7:Q7) -> 0
B8: 5071 | C8: Anpassningar lokaler | D8: 5071 Anpassningar lokaler | R8: =SUM(F8:Q8) -> 0
B9: 5090 | C9: Övriga lokalkostnader | D9: 5090 Övriga lokalkostnader | R9: =SUM(F9:Q9) -> 0
B10: 5222 | C10: Leasing av inventarier och verktyg | D10: 5222 Leasing av inventarier och verktyg | R10: =SUM(F10:Q10) -> 0
B11: 5410 | C11: Förbrukningsinventarier | D11: 5410 Förbrukningsinventarier | R11: =SUM(F11:Q11) -> 0
B12: 5420 | C12: Dataprogram | D12: 5420 Dataprogram | R12: =SUM(F12:Q12) -> 0
B13: 5440 | C13: Förbrukningsemballage | D13: 5440 Förbrukningsemballage | R13: =SUM(F13:Q13) -> 0
B14: 5460 | C14: Förbrukningsmaterial | D14: 5460 Förbrukningsmaterial | F14: 10 | G14: 10 | H14: 10 | I14: 10 | J14: 10 | K14: 10 | L14: 10 | M14: 10 | N14: 10 | O14: 10 | P14: 10 | Q14: 10 | R14: =SUM(F14:Q14) -> 120
B15: 5462 | C15: Tes/Utveckl./prov förbrukning | D15: 5462 Tes/Utveckl./prov förbrukning | R15: =SUM(F15:Q15) -> 0
B16: 5463 | C16: Förbrukningsmaterial - verkstad | D16: 5463 Förbrukningsmaterial - verkstad | R16: =SUM(F16:Q16) -> 0
B17: 5464 | C17: Förbrukningsmtr/prov - svetsproduktion | D17: 5464 Förbrukningsmtr/prov - svetsproduktion | R17: =SUM(F17:Q17) -> 0
B18: 5465 | C18: Förbrukningsmaterial - kultillverkning | D18: 5465 Förbrukningsmaterial - kultillverkning | R18: =SUM(F18:Q18) -> 0
B19: 5466 | C19: Förbrukningsmaterial - Raptor | D19: 5466 Förbrukningsmaterial - Raptor | R19: =SUM(F19:Q19) -> 0
B20: 5480 | C20: Arbetskläder och skyddsmaterial | D20: 5480 Arbetskläder och skyddsmaterial | R20: =SUM(F20:Q20) -> 0
B21: 5500 | C21: Reparation och underhåll (gruppkonto) | D21: 5500 Reparation och underhåll (gruppkonto) | R21: =SUM(F21:Q21) -> 0
B22: 5611 | C22: Drivmedel för Fordon/Maskiner | D22: 5611 Drivmedel för Fordon/Maskiner | R22: =SUM(F22:Q22) -> 0
B23: 5612 | C23: Försäkring och skatt för Fordon/Maskiner | D23: 5612 Försäkring och skatt för Fordon/Maskiner | R23: =SUM(F23:Q23) -> 0
B24: 5613 | C24: Rep och underhåll av Fordon/Maskiner | D24: 5613 Rep och underhåll av Fordon/Maskiner | R24: =SUM(F24:Q24) -> 0
B25: 5615 | C25: Leasingavgifter för Fordon/Maskiner | D25: 5615 Leasingavgifter för Fordon/Maskiner | F25: 11 | G25: 11 | H25: 11 | I25: 11 | J25: 11 | K25: 11 | L25: 11 | M25: 11 | N25: 11 | O25: 11 | P25: 11 | Q25: 11 | R25: =SUM(F25:Q25) -> 132
B26: 5616 | C26: Trängselavgift, avdragsgill | D26: 5616 Trängselavgift, avdragsgill | R26: =SUM(F26:Q26) -> 0
B27: 5619 | C27: Övriga personbilskostnader | D27: 5619 Övriga personbilskostnader | R27: =SUM(F27:Q27) -> 0
B28: 5720 | C28: Tull- och speditionskostnader | D28: 5720 Tull- och speditionskostnader | R28: =SUM(F28:Q28) -> 0
B29: 5831 | C29: Kost och logi i Sverige | D29: 5831 Kost och logi i Sverige | R29: =SUM(F29:Q29) -> 0
B30: 5832 | C30: Kost och logi i utlandet | D30: 5832 Kost och logi i utlandet | R30: =SUM(F30:Q30) -> 0
B31: 5890 | C31: Övriga resekostnader 25% | D31: 5890 Övriga resekostnader 25% | R31: =SUM(F31:Q31) -> 0
B32: 5891 | C32: Resekostnader i utlandet + flygbiljetter | D32: 5891 Resekostnader i utlandet + flygbiljetter | R32: =SUM(F32:Q32) -> 0
B33: 5892 | C33: Resekostnader 6% | D33: 5892 Resekostnader 6% | R33: =SUM(F33:Q33) -> 0
B34: 5900 | C34: Reklam och PR (gruppkonto) | D34: 5900 Reklam och PR (gruppkonto) | R34: =SUM(F34:Q34) -> 0
B35: 5930 | C35: Reklamtrycksaker och direktreklam | D35: 5930 Reklamtrycksaker och direktreklam | R35: =SUM(F35:Q35) -> 0
B36: 5940 | C36: Mässor o Utställningar | D36: 5940 Mässor o Utställningar | R36: =SUM(F36:Q36) -> 0
B37: 5941 | C37: Kundaktiviteter /projektstyrt | D37: 5941 Kundaktiviteter /projektstyrt | R37: =SUM(F37:Q37) -> 0
... B50: 6213 | C50: Telefonservice | D50: 6213 Telefonservice | R50: =SUM(F50:Q50) -> 0
B51: 6230 | C51: Datakommunikation | D51: 6230 Datakommunikation | F51: 10 | G51: 10 | H51: 10 | I51: 10 | J51: 10 | K51: 10 | L51: 10 | M51: 10 | N51: 10 | O51: 10 | P51: 10 | Q51: 10 | R51: =SUM(F51:Q51) -> 120 | S51: IOT Telia | U51: Potentiellt uppdateringsavtal eller serviceavtal
B52: 6250 | C52: Postbefordran | D52: 6250 Postbefordran | R52: =SUM(F52:Q52) -> 0
...

Sheet Admin
B1: Konto | C1: Namn | D1: Konto + namn | F1: 2601 | G1: 2602 | H1: 2603 | I1: 2604 | J1: 2605 | K1: 2606 | L1: 2607 | M1: 2608 | N1: 2609 | O1: 2610 | P1: 2611 | Q1: 2612 | R1: Summa 2026
B2: 5010 | C2: Lokalhyra | D2: 5010 Lokalhyra | R2: =SUM(F2:Q2) -> 0
B3: 5020 | C3: El för belysning | D3: 5020 El för belysning | R3: =SUM(F3:Q3) -> 0
B4: 5030 | C4: Värme | D4: 5030 Värme | R4: =SUM(F4:Q4) -> 0
B5: 5060 | C5: Städning | D5: 5060 Städning | R5: =SUM(F5:Q5) -> 0
B6: 5061 | C6: Renhållning | D6: 5061 Renhållning | R6: =SUM(F6:Q6) -> 0
B7: 5070 | C7: Reparation och underhåll av lokaler | D7: 5070 Reparation och underhåll av lokaler | R7: =SUM(F7:Q7) -> 0
B8: 5071 | C8: Anpassningar lokaler | D8: 5071 Anpassningar lokaler | R8: =SUM(F8:Q8) -> 0
B9: 5090 | C9: Övriga lokalkostnader | D9: 5090 Övriga lokalkostnader | R9: =SUM(F9:Q9) -> 0
B10: 5222 | C10: Leasing av inventarier och verktyg | D10: 5222 Leasing av inventarier och verktyg | R10: =SUM(F10:Q10) -> 0
B11: 5410 | C11: Förbrukningsinventarier | D11: 5410 Förbrukningsinventarier | F11: 2 | G11: 2 | H11: 2 | I11: 2 | J11: 2 | K11: 2 | L11: 2 | M11: 2 | N11: 2 | O11: 2 | P11: 2 | Q11: 2 | R11: =SUM(F11:Q11) -> 24
B12: 5420 | C12: Dataprogram | D12: 5420 Dataprogram | F12: =250/12 -> 20.833333 | G12: =250/12 -> 20.833333 | H12: =250/12 -> 20.833333 | I12: =250/12 -> 20.833333 | J12: =250/12 -> 20.833333 | K12: =250/12 -> 20.833333 | L12: =250/12 -> 20.833333 | M12: =250/12 -> 20.833333 | ... Q12: =250/12 -> 20.833333 | R12: =SUM(F12:Q12) -> 250 | S12: Monitor + annat
B13: 5440 | C13: Förbrukningsemballage | D13: 5440 Förbrukningsemballage | R13: =SUM(F13:Q13) -> 0
B14: 5460 | C14: Förbrukningsmaterial | D14: 5460 Förbrukningsmaterial | R14: =SUM(F14:Q14) -> 0
B15: 5462 | C15: Tes/Utveckl./prov förbrukning | D15: 5462 Tes/Utveckl./prov förbrukning | R15: =SUM(F15:Q15) -> 0
B16: 5463 | C16: Förbrukningsmaterial - verkstad | D16: 5463 Förbrukningsmaterial - verkstad | R16: =SUM(F16:Q16) -> 0
B17: 5464 | C17: Förbrukningsmtr/prov - svetsproduktion | D17: 5464 Förbrukningsmtr/prov - svetsproduktion | R17: =SUM(F17:Q17) -> 0
B18: 5465 | C18: Förbrukningsmaterial - kultillverkning | D18: 5465 Förbrukningsmaterial - kultillverkning | R18: =SUM(F18:Q18) -> 0
B19: 5466 | C19: Förbrukningsmaterial - Raptor | D19: 5466 Förbrukningsmaterial - Raptor | R19: =SUM(F19:Q19) -> 0
B20: 5480 | C20: Arbetskläder och skyddsmaterial | D20: 5480 Arbetskläder och skyddsmaterial | R20: =SUM(F20:Q20) -> 0
B21: 5500 | C21: Reparation och underhåll (gruppkonto) | D21: 5500 Reparation och underhåll (gruppkonto) | R21: =SUM(F21:Q21) -> 0
